Workbook

Sheet План недели
A1: План недели и предварительное количество точек | B1: План недели и предварительное количество точек | C1: План недели и предварительное количество точек | D1: План недели и предварительное количество точек | E1: План недели и предварительное количество точек | F1: План недели и предварительное количество точек
A2: Отчётный период: среда включительно — следующая среда исключительно. В среду до штаба сохраняется завершённый период; после штаба укажите его дату в ячейке F4, и план сразу переключится на новый период. В остальные дни период меняется автоматически. | B2: Неделя определяется по понедельнику. Итог учитывает все строки календаря, кроме отменённых. Если у объекта не заполнен POINTS_COUNT, итог будет неполным. | C2: Неделя определяется по понедельнику. Итог учитывает все строки календаря, кроме отменённых. Если у объекта не заполнен POINTS_COUNT, итог будет неполным. | D2: Неделя определяется по понедельнику. Итог учитывает все строки календаря, кроме отменённых. Если у объекта не заполнен POINTS_COUNT, итог будет неполным. | E2: Неделя определяется по понедельнику. Итог учитывает все строки календаря, кроме отменённых. Если у объекта не заполнен POINTS_COUNT, итог будет неполным. | F2: Неделя определяется по понедельнику. Итог учитывает все строки календаря, кроме отменённых. Если у объекта не заполнен POINTS_COUNT, итог будет неполным.
A4: Период с | B4: =TODAY()-MOD(WEEKDAY(TODAY(),2)-3,7)-IF(AND(WEEKDAY(TODAY(),2)=3,$F$4<>TODAY()),7,0) -> 46225 | C4: до (не включая) | D4: =B4+7 -> 46232 | E4: Дата последнего штаба | F4: 46225
A5: После каждого штаба меняйте только жёлтую ячейку F4 на дату проведённого штаба.
A6: Выездов / объектов | C6: Предварительно точек | E6: Без количества точек
A7: =COUNTIFS(Выезды!$B$5:$B$1883,">="&$B$4,Выезды!$B$5:$B$1883,"<"&$D$4,Выезды!$D$5:$D$1883,"<>",Выезды!$G$5:$G$1883,"<>Отменён") -> 7 | C7: =SUMIFS(Выезды!$I$5:$I$1883,Выезды!$B$5:$B$1883,">="&$B$4,Выезды!$B$5:$B$1883,"<"&$D$4,Выезды!$D$5:$D$1883,"<>",Выезды!$G$5:$G$1883,"<>Отменён") -> 1895 | E7: =COUNTIFS(Выезды!$B$5:$B$1883,">="&$B$4,Выезды!$B$5:$B$1883,"<"&$D$4,Выезды!$D$5:$D$1883,"<>",Выезды!$I$5:$I$1883,"",Выезды!$G$5:$G$1883,"<>Отменён") -> 0
A10: Дата | B10: День | C10: Объектов | D10: Точек | E10: Запланировано | F10: Выполнено
A11: =$B$4 -> 46225 | B11: =CHOOSE(WEEKDAY(A11,2),"Пн","Вт","Ср","Чт","Пт","Сб","Вс") -> Ср | C11: =COUNTIFS(Выезды!$B$5:$B$1883,A11,Выезды!$D$5:$D$1883,"<>",Выезды!$G$5:$G$1883,"<>Отменён") -> 2 | D11: =SUMIFS(Выезды!$I$5:$I$1883,Выезды!$B$5:$B$1883,A11,Выезды!$D$5:$D$1883,"<>",Выезды!$G$5:$G$1883,"<>Отменён") -> 351 | E11: =COUNTIFS(Выезды!$B$5:$B$1883,A11,Выезды!$D$5:$D$1883,"<>",Выезды!$G$5:$G$1883,"Запланирован") -> 0 | F11: =COUNTIFS(Выезды!$B$5:$B$1883,A11,Выезды!$D$5:$D$1883,"<>",Выезды!$G$5:$G$1883,"Выполнен") -> 2
A12: =A11+1 -> 46226 | B12: =CHOOSE(WEEKDAY(A12,2),"Пн","Вт","Ср","Чт","Пт","Сб","Вс") -> Чт | C12: =COUNTIFS(Выезды!$B$5:$B$1883,A12,Выезды!$D$5:$D$1883,"<>",Выезды!$G$5:$G$1883,"<>Отменён") -> 1 | D12: =SUMIFS(Выезды!$I$5:$I$1883,Выезды!$B$5:$B$1883,A12,Выезды!$D$5:$D$1883,"<>",Выезды!$G$5:$G$1883,"<>Отменён") -> 526 | E12: =COUNTIFS(Выезды!$B$5:$B$1883,A12,Выезды!$D$5:$D$1883,"<>",Выезды!$G$5:$G$1883,"Запланирован") -> 0 | F12: =COUNTIFS(Выезды!$B$5:$B$1883,A12,Выезды!$D$5:$D$1883,"<>",Выезды!$G$5:$G$1883,"Выполнен") -> 1
A13: =A12+1 -> 46227 | B13: =CHOOSE(WEEKDAY(A13,2),"Пн","Вт","Ср","Чт","Пт","Сб","Вс") -> Пт | C13: =COUNTIFS(Выезды!$B$5:$B$1883,A13,Выезды!$D$5:$D$1883,"<>",Выезды!$G$5:$G$1883,"<>Отменён") -> 1 | D13: =SUMIFS(Выезды!$I$5:$I$1883,Выезды!$B$5:$B$1883,A13,Выезды!$D$5:$D$1883,"<>",Выезды!$G$5:$G$1883,"<>Отменён") -> 151 | E13: =COUNTIFS(Выезды!$B$5:$B$1883,A13,Выезды!$D$5:$D$1883,"<>",Выезды!$G$5:$G$1883,"Запланирован") -> 0 | F13: =COUNTIFS(Выезды!$B$5:$B$1883,A13,Выезды!$D$5:$D$1883,"<>",Выезды!$G$5:$G$1883,"Выполнен") -> 1
A14: =A13+1 -> 46228 | B14: =CHOOSE(WEEKDAY(A14,2),"Пн","Вт","Ср","Чт","Пт","Сб","Вс") -> Сб | C14: =COUNTIFS(Выезды!$B$5:$B$1883,A14,Выезды!$D$5:$D$1883,"<>",Выезды!$G$5:$G$1883,"<>Отменён") -> 0 | D14: =SUMIFS(Выезды!$I$5:$I$1883,Выезды!$B$5:$B$1883,A14,Выезды!$D$5:$D$1883,"<>",Выезды!$G$5:$G$1883,"<>Отменён") -> 0 | E14: =COUNTIFS(Выезды!$B$5:$B$1883,A14,Выезды!$D$5:$D$1883,"<>",Выезды!$G$5:$G$1883,"Запланирован") -> 0 | F14: =COUNTIFS(Выезды!$B$5:$B$1883,A14,Выезды!$D$5:$D$1883,"<>",Выезды!$G$5:$G$1883,"Выполнен") -> 0
A15: =A14+1 -> 46229 | B15: =CHOOSE(WEEKDAY(A15,2),"Пн","Вт","Ср","Чт","Пт","Сб","Вс") -> Вс | C15: =COUNTIFS(Выезды!$B$5:$B$1883,A15,Выезды!$D$5:$D$1883,"<>",Выезды!$G$5:$G$1883,"<>Отменён") -> 0 | D15: =SUMIFS(Выезды!$I$5:$I$1883,Выезды!$B$5:$B$1883,A15,Выезды!$D$5:$D$1883,"<>",Выезды!$G$5:$G$1883,"<>Отменён") -> 0 | E15: =COUNTIFS(Выезды!$B$5:$B$1883,A15,Выезды!$D$5:$D$1883,"<>",Выезды!$G$5:$G$1883,"Запланирован") -> 0 | F15: =COUNTIFS(Выезды!$B$5:$B$1883,A15,Выезды!$D$5:$D$1883,"<>",Выезды!$G$5:$G$1883,"Выполнен") -> 0
A16: =A15+1 -> 46230 | B16: =CHOOSE(WEEKDAY(A16,2),"Пн","Вт","Ср","Чт","Пт","Сб","Вс") -> Пн | C16: =COUNTIFS(Выезды!$B$5:$B$1883,A16,Выезды!$D$5:$D$1883,"<>",Выезды!$G$5:$G$1883,"<>Отменён") -> 2 | D16: =SUMIFS(Выезды!$I$5:$I$1883,Выезды!$B$5:$B$1883,A16,Выезды!$D$5:$D$1883,"<>",Выезды!$G$5:$G$1883,"<>Отменён") -> 501 | E16: =COUNTIFS(Выезды!$B$5:$B$1883,A16,Выезды!$D$5:$D$1883,"<>",Выезды!$G$5:$G$1883,"Запланирован") -> 2 | F16: =COUNTIFS(Выезды!$B$5:$B$1883,A16,Выезды!$D$5:$D$1883,"<>",Выезды!$G$5:$G$1883,"Выполнен") -> 0
A17: =A16+1 -> 46231 | B17: =CHOOSE(WEEKDAY(A17,2),"Пн","Вт","Ср","Чт","Пт","Сб","Вс") -> Вт | C17: =COUNTIFS(Выезды!$B$5:$B$1883,A17,Выезды!$D$5:$D$1883,"<>",Выезды!$G$5:$G$1883,"<>Отменён") -> 1 | D17: =SUMIFS(Выезды!$I$5:$I$1883,Выезды!$B$5:$B$1883,A17,Выезды!$D$5:$D$1883,"<>",Выезды!$G$5:$G$1883,"<>Отменён") -> 366 | E17: =COUNTIFS(Выезды!$B$5:$B$1883,A17,Выезды!$D$5:$D$1883,"<>",Выезды!$G$5:$G$1883,"Запланирован") -> 1 | F17: =COUNTIFS(Выезды!$B$5:$B$1883,A17,Выезды!$D$5:$D$1883,"<>",Выезды!$G$5:$G$1883,"Выполнен") -> 0
A20: Контроль заполнения
A21: Объекты без количества точек | B21: =COUNTIF(Объекты!$B$5:$B$200,"<>")-COUNT(Объекты!$C$5:$C$200) -> 0 | C21: Заполните жёлтый столбец «Количество точек» на листе «Объекты»
A22: Объекты без ALBUM_URL | B22: =COUNTIFS(Объекты!$B$5:$B$200,"<>",Объекты!$J$5:$J$200,"") -> 0 | C22: Проверьте публичную ссылку на альбом
A23: Строки календаря без сотрудника | B23: =COUNTIFS(Выезды!$B$5:$B$1883,">="&$B$4,Выезды!$B$5:$B$1883,"<"&$D$4,Выезды!$D$5:$D$1883,"<>",Выезды!$E$5:$E$1883,"",Выезды!$G$5:$G$1883,"<>Отменён") -> 0 | C23: Выберите сотрудника в календаре
A24: Строки календаря без статуса | B24: =COUNTIFS(Выезды!$B$5:$B$1883,">="&$B$4,Выезды!$B$5:$B$1883,"<"&$D$4,Выезды!$D$5:$D$1883,"<>",Выезды!$G$5:$G$1883,"") -> 0 | C24: Выберите статус в календаре
A27: Объекты отчётного периода
A28: Дата | B28: Объект | C28: Сотрудник | D28: Статус | E28: Количество точек | F28: Итог
A29: {=IFERROR(INDEX(Выезды!$B$5:$B$1883,MATCH(ROW()-28,Выезды!$K$5:$K$1883,0)),"")} -> 46225 | B29: {=IFERROR(INDEX(Выезды!$D$5:$D$1883,MATCH(ROW()-28,Выезды!$K$5:$K$1883,0)),"")} -> ст. Бульвар Генерала Карбышева | C29: {=IFERROR(INDEX(Выезды!$E$5:$E$1883,MATCH(ROW()-28,Выезды!$K$5:$K$1883,0)),"")} -> Струков Д.М. | D29: {=IFERROR(INDEX(Выезды!$G$5:$G$1883,MATCH(ROW()-28,Выезды!$K$5:$K$1883,0)),"")} -> Выполнен | E29: {=IFERROR(INDEX(Выезды!$I$5:$I$1883,MATCH(ROW()-28,Выезды!$K$5:$K$1883,0)),"")} -> 200 | F29: =SUM(E29:E59) -> 1895
A30: {=IFERROR(INDEX(Выезды!$B$5:$B$1883,MATCH(ROW()-28,Выезды!$K$5:$K$1883,0)),"")} -> 46225 | B30: {=IFERROR(INDEX(Выезды!$D$5:$D$1883,MATCH(ROW()-28,Выезды!$K$5:$K$1883,0)),"")} -> Ситуационный центр | C30: {=IFERROR(INDEX(Выезды!$E$5:$E$1883,MATCH(ROW()-28,Выезды!$K$5:$K$1883,0)),"")} -> Сафонов М.С. | D30: {=IFERROR(INDEX(Выезды!$G$5:$G$1883,MATCH(ROW()-28,Выезды!$K$5:$K$1883,0)),"")} -> Выполнен | E30: {=IFERROR(INDEX(Выезды!$I$5:$I$1883,MATCH(ROW()-28,Выезды!$K$5:$K$1883,0)),"")} -> 151
A31: {=IFERROR(INDEX(Выезды!$B$5:$B$1883,MATCH(ROW()-28,Выезды!$K$5:$K$1883,0)),"")} -> 46226 | B31: {=IFERROR(INDEX(Выезды!$D$5:$D$1883,MATCH(ROW()-28,Выезды!$K$5:$K$1883,0)),"")} -> ст. Новорижская | C31: {=IFERROR(INDEX(Выезды!$E$5:$E$1883,MATCH(ROW()-28,Выезды!$K$5:$K$1883,0)),"")} -> Сафонов М.С. | D31: {=IFERROR(INDEX(Выезды!$G$5:$G$1883,MATCH(ROW()-28,Выезды!$K$5:$K$1883,0)),"")} -> Выполнен | E31: {=IFERROR(INDEX(Выезды!$I$5:$I$1883,MATCH(ROW()-28,Выезды!$K$5:$K$1883,0)),"")} -> 526
A32: {=IFERROR(INDEX(Выезды!$B$5:$B$1883,MATCH(ROW()-28,Выезды!$K$5:$K$1883,0)),"")} -> 46227 | B32: {=IFERROR(INDEX(Выезды!$D$5:$D$1883,MATCH(ROW()-28,Выезды!$K$5:$K$1883,0)),"")} -> Ситуационный центр | C32: {=IFERROR(INDEX(Выезды!$E$5:$E$1883,MATCH(ROW()-28,Выезды!$K$5:$K$1883,0)),"")} -> Сафонов М.С. | D32: {=IFERROR(INDEX(Выезды!$G$5:$G$1883,MATCH(ROW()-28,Выезды!$K$5:$K$1883,0)),"")} -> Выполнен | E32: {=IFERROR(INDEX(Выезды!$I$5:$I$1883,MATCH(ROW()-28,Выезды!$K$5:$K$1883,0)),"")} -> 151
A33: {=IFERROR(INDEX(Выезды!$B$5:$B$1883,MATCH(ROW()-28,Выезды!$K$5:$K$1883,0)),"")} -> 46230 | B33: {=IFERROR(INDEX(Выезды!$D$5:$D$1883,MATCH(ROW()-28,Выезды!$K$5:$K$1883,0)),"")} -> Ситуационный центр | C33: {=IFERROR(INDEX(Выезды!$E$5:$E$1883,MATCH(ROW()-28,Выезды!$K$5:$K$1883,0)),"")} -> Сафонов М.С. | D33: {=IFERROR(INDEX(Выезды!$G$5:$G$1883,MATCH(ROW()-28,Выезды!$K$5:$K$1883,0)),"")} -> Запланирован | E33: {=IFERROR(INDEX(Выезды!$I$5:$I$1883,MATCH(ROW()-28,Выезды!$K$5:$K$1883,0)),"")} -> 151
A34: {=IFERROR(INDEX(Выезды!$B$5:$B$1883,MATCH(ROW()-28,Выезды!$K$5:$K$1883,0)),"")} -> 46230 | B34: {=IFERROR(INDEX(Выезды!$D$5:$D$1883,MATCH(ROW()-28,Выезды!$K$5:$K$1883,0)),"")} -> ст. Липовая Роща | C34: {=IFERROR(INDEX(Выезды!$E$5:$E$1883,MATCH(ROW()-28,Выезды!$K$5:$K$1883,0)),"")} -> Сафонов М.С. | D34: {=IFERROR(INDEX(Выезды!$G$5:$G$1883,MATCH(ROW()-28,Выезды!$K$5:$K$1883,0)),"")} -> Запланирован | E34: {=IFERROR(INDEX(Выезды!$I$5:$I$1883,MATCH(ROW()-28,Выезды!$K$5:$K$1883,0)),"")} -> 350
A35: {=IFERROR(INDEX(Выезды!$B$5:$B$1883,MATCH(ROW()-28,Выезды!$K$5:$K$1883,0)),"")} -> 46231 | B35: {=IFERROR(INDEX(Выезды!$D$5:$D$1883,MATCH(ROW()-28,Выезды!$K$5:$K$1883,0)),"")} -> ст. Звенигородская | C35: {=IFERROR(INDEX(Выезды!$E$5:$E$1883,MATCH(ROW()-28,Выезды!$K$5:$K$1883,0)),"")} -> Сафонов М.С. | D35: {=IFERROR(INDEX(Выезды!$G$5:$G$1883,MATCH(ROW()-28,Выезды!$K$5:$K$1883,0)),"")} -> Запланирован | E35: {=IFERROR(INDEX(Выезды!$I$5:$I$1883,MATCH(ROW()-28,Выезды!$K$5:$K$1883,0)),"")} -> 366
A36: {=IFERROR(INDEX(Выезды!$B$5:$B$1883,MATCH(ROW()-28,Выезды!$K$5:$K$1883,0)),"")} | B36: {=IFERROR(INDEX(Выезды!$D$5:$D$1883,MATCH(ROW()-28,Выезды!$K$5:$K$1883,0)),"")} | C36: {=IFERROR(INDEX(Выезды!$E$5:$E$1883,MATCH(ROW()-28,Выезды!$K$5:$K$1883,0)),"")} | D36: {=IFERROR(INDEX(Выезды!$G$5:$G$1883,MATCH(ROW()-28,Выезды!$K$5:$K$1883,0)),"")} | E36: {=IFERROR(INDEX(Выезды!$I$5:$I$1883,MATCH(ROW()-28,Выезды!$K$5:$K$1883,0)),"")}
A37: {=IFERROR(INDEX(Выезды!$B$5:$B$1883,MATCH(ROW()-28,Выезды!$K$5:$K$1883,0)),"")} | B37: {=IFERROR(INDEX(Выезды!$D$5:$D$1883,MATCH(ROW()-28,Выезды!$K$5:$K$1883,0)),"")} | C37: {=IFERROR(INDEX(Выезды!$E$5:$E$1883,MATCH(ROW()-28,Выезды!$K$5:$K$1883,0)),"")} | D37: {=IFERROR(INDEX(Выезды!$G$5:$G$1883,MATCH(ROW()-28,Выезды!$K$5:$K$1883,0)),"")} | E37: {=IFERROR(INDEX(Выезды!$I$5:$I$1883,MATCH(ROW()-28,Выезды!$K$5:$K$1883,0)),"")}
A38: {=IFERROR(INDEX(Выезды!$B$5:$B$1883,MATCH(ROW()-28,Выезды!$K$5:$K$1883,0)),"")} | B38: {=IFERROR(INDEX(Выезды!$D$5:$D$1883,MATCH(ROW()-28,Выезды!$K$5:$K$1883,0)),"")} | C38: {=IFERROR(INDEX(Выезды!$E$5:$E$1883,MATCH(ROW()-28,Выезды!$K$5:$K$1883,0)),"")} | D38: {=IFERROR(INDEX(Выезды!$G$5:$G$1883,MATCH(ROW()-28,Выезды!$K$5:$K$1883,0)),"")} | E38: {=IFERROR(INDEX(Выезды!$I$5:$I$1883,MATCH(ROW()-28,Выезды!$K$5:$K$1883,0)),"")}
A39: {=IFERROR(INDEX(Выезды!$B$5:$B$1883,MATCH(ROW()-28,Выезды!$K$5:$K$1883,0)),"")} | B39: {=IFERROR(INDEX(Выезды!$D$5:$D$1883,MATCH(ROW()-28,Выезды!$K$5:$K$1883,0)),"")} | C39: {=IFERROR(INDEX(Выезды!$E$5:$E$1883,MATCH(ROW()-28,Выезды!$K$5:$K$1883,0)),"")} | D39: {=IFERROR(INDEX(Выезды!$G$5:$G$1883,MATCH(ROW()-28,Выезды!$K$5:$K$1883,0)),"")} | E39: {=IFERROR(INDEX(Выезды!$I$5:$I$1883,MATCH(ROW()-28,Выезды!$K$5:$K$1883,0)),"")}
A40: {=IFERROR(INDEX(Выезды!$B$5:$B$1883,MATCH(ROW()-28,Выезды!$K$5:$K$1883,0)),"")} | B40: {=IFERROR(INDEX(Выезды!$D$5:$D$1883,MATCH(ROW()-28,Выезды!$K$5:$K$1883,0)),"")} | C40: {=IFERROR(INDEX(Выезды!$E$5:$E$1883,MATCH(ROW()-28,Выезды!$K$5:$K$1883,0)),"")} | D40: {=IFERROR(INDEX(Выезды!$G$5:$G$1883,MATCH(ROW()-28,Выезды!$K$5:$K$1883,0)),"")} | E40: {=IFERROR(INDEX(Выезды!$I$5:$I$1883,MATCH(ROW()-28,Выезды!$K$5:$K$1883,0)),"")}
A41: {=IFERROR(INDEX(Выезды!$B$5:$B$1883,MATCH(ROW()-28,Выезды!$K$5:$K$1883,0)),"")} | B41: {=IFERROR(INDEX(Выезды!$D$5:$D$1883,MATCH(ROW()-28,Выезды!$K$5:$K$1883,0)),"")} | C41: {=IFERROR(INDEX(Выезды!$E$5:$E$1883,MATCH(ROW()-28,Выезды!$K$5:$K$1883,0)),"")} | D41: {=IFERROR(INDEX(Выезды!$G$5:$G$1883,MATCH(ROW()-28,Выезды!$K$5:$K$1883,0)),"")} | E41: {=IFERROR(INDEX(Выезды!$I$5:$I$1883,MATCH(ROW()-28,Выезды!$K$5:$K$1883,0)),"")}
... A59: {=IFERROR(INDEX(Выезды!$B$5:$B$1883,MATCH(ROW()-28,Выезды!$K$5:$K$1883,0)),"")} | B59: {=IFERROR(INDEX(Выезды!$D$5:$D$1883,MATCH(ROW()-28,Выезды!$K$5:$K$1883,0)),"")} | C59: {=IFERROR(INDEX(Выезды!$E$5:$E$1883,MATCH(ROW()-28,Выезды!$K$5:$K$1883,0)),"")} | D59: {=IFERROR(INDEX(Выезды!$G$5:$G$1883,MATCH(ROW()-28,Выезды!$K$5:$K$1883,0)),"")} | E59: {=IFERROR(INDEX(Выезды!$I$5:$I$1883,MATCH(ROW()-28,Выезды!$K$5:$K$1883,0)),"")}

Sheet Выезды
A1: Календарь выездов | B1: Календарь выездов | C1: Календарь выездов | D1: Календарь выездов | E1: Календарь выездов | F1: Календарь выездов | G1: Календарь выездов | H1: Календарь выездов | I1: Календарь выездов | J1: Календарь выездов
A2: Одна подготовленная строка на каждую дату с 01.01.2026 по 31.12.2030. Если в день несколько выездов, вставьте новую строку внутри таблицы сразу после нужной даты и повторите VISIT_DATE. VISIT_ID, день недели, количество точек и отчётный период рассчитываются автоматически; новая строка попадёт в статистику. | B2: Одна строка — один объект в один день. Чтобы добавить несколько объектов в один выезд, добавьте несколько строк с одинаковой датой и сотрудником. POINTS_COUNT и WEEK_START рассчитываются автоматически. | C2: Одна строка — один объект в один день. Чтобы добавить несколько объектов в один выезд, добавьте несколько строк с одинаковой датой и сотрудником. POINTS_COUNT и WEEK_START рассчитываются автоматически. | D2: Одна строка — один объект в один день. Чтобы добавить несколько объектов в один выезд, добавьте несколько строк с одинаковой датой и сотрудником. POINTS_COUNT и WEEK_START рассчитываются автоматически. | E2: Одна строка — один объект в один день. Чтобы добавить несколько объектов в один выезд, добавьте несколько строк с одинаковой датой и сотрудником. POINTS_COUNT и WEEK_START рассчитываются автоматически. | F2: Одна строка — один объект в один день. Чтобы добавить несколько объектов в один выезд, добавьте несколько строк с одинаковой датой и сотрудником. POINTS_COUNT и WEEK_START рассчитываются автоматически. | G2: Одна строка — один объект в один день. Чтобы добавить несколько объектов в один выезд, добавьте несколько строк с одинаковой датой и сотрудником. POINTS_COUNT и WEEK_START рассчитываются автоматически. | H2: Одна строка — один объект в один день. Чтобы добавить несколько объектов в один выезд, добавьте несколько строк с одинаковой датой и сотрудником. POINTS_COUNT и WEEK_START рассчитываются автоматически. | I2: Одна строка — один объект в один день. Чтобы добавить несколько объектов в один выезд, добавьте несколько строк с одинаковой датой и сотрудником. POINTS_COUNT и WEEK_START рассчитываются автоматически. | J2: Одна строка — один объект в один день. Чтобы добавить несколько объектов в один выезд, добавьте несколько строк с одинаковой датой и сотрудником. POINTS_COUNT и WEEK_START рассчитываются автоматически.
A4: VISIT_ID | B4: VISIT_DATE | C4: День недели | D4: OBJECTS | E4: EMPLOYEE | F4: WORK_TYPE | G4: STATUS | H4: COMMENT | I4: Количество точек | J4: Начало отчётного периода | K4: № в текущем периоде
A5: =IF(B5="","","VIS_"&(YEAR(B5)*10000+MONTH(B5)*100+DAY(B5))&"_"&IF(COUNTIF($B$5:B5,B5)<10,"00"&COUNTIF($B$5:B5,B5),IF(COUNTIF($B$5:B5,B5)<100,"0"&COUNTIF($B$5:B5,B5),COUNTIF($B$5:B5,B5)))) -> VIS_20260101_001 | B5: 46023 | C5: =IF(B5="","",CHOOSE(WEEKDAY(B5,2),"Пн","Вт","Ср","Чт","Пт","Сб","Вс")) -> Чт | J5: =IF(B5="","",B5-MOD(WEEKDAY(B5,2)-3,7)) -> 46022 | K5: =IF(AND(B5>='План недели'!$B$4,B5<'План недели'!$D$4,D5<>"",G5<>"Отменён"),COUNTIFS($B$5:B5,">="&'План недели'!$B$4,$B$5:B5,"<"&'План недели'!$D$4,$D$5:D5,"<>",$G$5:G5,"<>Отменён"),"")
A6: =IF(B6="","","VIS_"&(YEAR(B6)*10000+MONTH(B6)*100+DAY(B6))&"_"&IF(COUNTIF($B$5:B6,B6)<10,"00"&COUNTIF($B$5:B6,B6),IF(COUNTIF($B$5:B6,B6)<100,"0"&COUNTIF($B$5:B6,B6),COUNTIF($B$5:B6,B6)))) -> VIS_20260102_001 | B6: 46024 | C6: =IF(B6="","",CHOOSE(WEEKDAY(B6,2),"Пн","Вт","Ср","Чт","Пт","Сб","Вс")) -> Пт | J6: =IF(B6="","",B6-MOD(WEEKDAY(B6,2)-3,7)) -> 46022 | K6: =IF(AND(B6>='План недели'!$B$4,B6<'План недели'!$D$4,D6<>"",G6<>"Отменён"),COUNTIFS($B$5:B6,">="&'План недели'!$B$4,$B$5:B6,"<"&'План недели'!$D$4,$D$5:D6,"<>",$G$5:G6,"<>Отменён"),"")
A7: =IF(B7="","","VIS_"&(YEAR(B7)*10000+MONTH(B7)*100+DAY(B7))&"_"&IF(COUNTIF($B$5:B7,B7)<10,"00"&COUNTIF($B$5:B7,B7),IF(COUNTIF($B$5:B7,B7)<100,"0"&COUNTIF($B$5:B7,B7),COUNTIF($B$5:B7,B7)))) -> VIS_20260103_001 | B7: 46025 | C7: =IF(B7="","",CHOOSE(WEEKDAY(B7,2),"Пн","Вт","Ср","Чт","Пт","Сб","Вс")) -> Сб | J7: =IF(B7="","",B7-MOD(WEEKDAY(B7,2)-3,7)) -> 46022 | K7: =IF(AND(B7>='План недели'!$B$4,B7<'План недели'!$D$4,D7<>"",G7<>"Отменён"),COUNTIFS($B$5:B7,">="&'План недели'!$B$4,$B$5:B7,"<"&'План недели'!$D$4,$D$5:D7,"<>",$G$5:G7,"<>Отменён"),"")
A8: =IF(B8="","","VIS_"&(YEAR(B8)*10000+MONTH(B8)*100+DAY(B8))&"_"&IF(COUNTIF($B$5:B8,B8)<10,"00"&COUNTIF($B$5:B8,B8),IF(COUNTIF($B$5:B8,B8)<100,"0"&COUNTIF($B$5:B8,B8),COUNTIF($B$5:B8,B8)))) -> VIS_20260104_001 | B8: 46026 | C8: =IF(B8="","",CHOOSE(WEEKDAY(B8,2),"Пн","Вт","Ср","Чт","Пт","Сб","Вс")) -> Вс | J8: =IF(B8="","",B8-MOD(WEEKDAY(B8,2)-3,7)) -> 46022 | K8: =IF(AND(B8>='План недели'!$B$4,B8<'План недели'!$D$4,D8<>"",G8<>"Отменён"),COUNTIFS($B$5:B8,">="&'План недели'!$B$4,$B$5:B8,"<"&'План недели'!$D$4,$D$5:D8,"<>",$G$5:G8,"<>Отменён"),"")
A9: =IF(B9="","","VIS_"&(YEAR(B9)*10000+MONTH(B9)*100+DAY(B9))&"_"&IF(COUNTIF($B$5:B9,B9)<10,"00"&COUNTIF($B$5:B9,B9),IF(COUNTIF($B$5:B9,B9)<100,"0"&COUNTIF($B$5:B9,B9),COUNTIF($B$5:B9,B9)))) -> VIS_20260105_001 | B9: 46027 | C9: =IF(B9="","",CHOOSE(WEEKDAY(B9,2),"Пн","Вт","Ср","Чт","Пт","Сб","Вс")) -> Пн | J9: =IF(B9="","",B9-MOD(WEEKDAY(B9,2)-3,7)) -> 46022 | K9: =IF(AND(B9>='План недели'!$B$4,B9<'План недели'!$D$4,D9<>"",G9<>"Отменён"),COUNTIFS($B$5:B9,">="&'План недели'!$B$4,$B$5:B9,"<"&'План недели'!$D$4,$D$5:D9,"<>",$G$5:G9,"<>Отменён"),"")
A10: =IF(B10="","","VIS_"&(YEAR(B10)*10000+MONTH(B10)*100+DAY(B10))&"_"&IF(COUNTIF($B$5:B10,B10)<10,"00"&COUNTIF($B$5:B10,B10),IF(COUNTIF($B$5:B10,B10)<100,"0"&COUNTIF($B$5:B10,B10),COUNTIF($B$5:B10,B10)))) -> VIS_20260106_001 | B10: 46028 | C10: =IF(B10="","",CHOOSE(WEEKDAY(B10,2),"Пн","Вт","Ср","Чт","Пт","Сб","Вс")) -> Вт | J10: =IF(B10="","",B10-MOD(WEEKDAY(B10,2)-3,7)) -> 46022 | K10: =IF(AND(B10>='План недели'!$B$4,B10<'План недели'!$D$4,D10<>"",G10<>"Отменён"),COUNTIFS($B$5:B10,">="&'План недели'!$B$4,$B$5:B10,"<"&'План недели'!$D$4,$D$5:D10,"<>",$G$5:G10,"<>Отменён"),"")
A11: =IF(B11="","","VIS_"&(YEAR(B11)*10000+MONTH(B11)*100+DAY(B11))&"_"&IF(COUNTIF($B$5:B11,B11)<10,"00"&COUNTIF($B$5:B11,B11),IF(COUNTIF($B$5:B11,B11)<100,"0"&COUNTIF($B$5:B11,B11),COUNTIF($B$5:B11,B11)))) -> VIS_20260107_001 | B11: 46029 | C11: =IF(B11="","",CHOOSE(WEEKDAY(B11,2),"Пн","Вт","Ср","Чт","Пт","Сб","Вс")) -> Ср | J11: =IF(B11="","",B11-MOD(WEEKDAY(B11,2)-3,7)) -> 46029 | K11: =IF(AND(B11>='План недели'!$B$4,B11<'План недели'!$D$4,D11<>"",G11<>"Отменён"),COUNTIFS($B$5:B11,">="&'План недели'!$B$4,$B$5:B11,"<"&'План недели'!$D$4,$D$5:D11,"<>",$G$5:G11,"<>Отменён"),"")
A12: =IF(B12="","","VIS_"&(YEAR(B12)*10000+MONTH(B12)*100+DAY(B12))&"_"&IF(COUNTIF($B$5:B12,B12)<10,"00"&COUNTIF($B$5:B12,B12),IF(COUNTIF($B$5:B12,B12)<100,"0"&COUNTIF($B$5:B12,B12),COUNTIF($B$5:B12,B12)))) -> VIS_20260108_001 | B12: 46030 | C12: =IF(B12="","",CHOOSE(WEEKDAY(B12,2),"Пн","Вт","Ср","Чт","Пт","Сб","Вс")) -> Чт | J12: =IF(B12="","",B12-MOD(WEEKDAY(B12,2)-3,7)) -> 46029 | K12: =IF(AND(B12>='План недели'!$B$4,B12<'План недели'!$D$4,D12<>"",G12<>"Отменён"),COUNTIFS($B$5:B12,">="&'План недели'!$B$4,$B$5:B12,"<"&'План недели'!$D$4,$D$5:D12,"<>",$G$5:G12,"<>Отменён"),"")
A13: =IF(B13="","","VIS_"&(YEAR(B13)*10000+MONTH(B13)*100+DAY(B13))&"_"&IF(COUNTIF($B$5:B13,B13)<10,"00"&COUNTIF($B$5:B13,B13),IF(COUNTIF($B$5:B13,B13)<100,"0"&COUNTIF($B$5:B13,B13),COUNTIF($B$5:B13,B13)))) -> VIS_20260109_001 | B13: 46031 | C13: =IF(B13="","",CHOOSE(WEEKDAY(B13,2),"Пн","Вт","Ср","Чт","Пт","Сб","Вс")) -> Пт | J13: =IF(B13="","",B13-MOD(WEEKDAY(B13,2)-3,7)) -> 46029 | K13: =IF(AND(B13>='План недели'!$B$4,B13<'План недели'!$D$4,D13<>"",G13<>"Отменён"),COUNTIFS($B$5:B13,">="&'План недели'!$B$4,$B$5:B13,"<"&'План недели'!$D$4,$D$5:D13,"<>",$G$5:G13,"<>Отменён"),"")
A14: =IF(B14="","","VIS_"&(YEAR(B14)*10000+MONTH(B14)*100+DAY(B14))&"_"&IF(COUNTIF($B$5:B14,B14)<10,"00"&COUNTIF($B$5:B14,B14),IF(COUNTIF($B$5:B14,B14)<100,"0"&COUNTIF($B$5:B14,B14),COUNTIF($B$5:B14,B14)))) -> VIS_20260110_001 | B14: 46032 | C14: =IF(B14="","",CHOOSE(WEEKDAY(B14,2),"Пн","Вт","Ср","Чт","Пт","Сб","Вс")) -> Сб | J14: =IF(B14="","",B14-MOD(WEEKDAY(B14,2)-3,7)) -> 46029 | K14: =IF(AND(B14>='План недели'!$B$4,B14<'План недели'!$D$4,D14<>"",G14<>"Отменён"),COUNTIFS($B$5:B14,">="&'План недели'!$B$4,$B$5:B14,"<"&'План недели'!$D$4,$D$5:D14,"<>",$G$5:G14,"<>Отменён"),"")
A15: =IF(B15="","","VIS_"&(YEAR(B15)*10000+MONTH(B15)*100+DAY(B15))&"_"&IF(COUNTIF($B$5:B15,B15)<10,"00"&COUNTIF($B$5:B15,B15),IF(COUNTIF($B$5:B15,B15)<100,"0"&COUNTIF($B$5:B15,B15),COUNTIF($B$5:B15,B15)))) -> VIS_20260111_001 | B15: 46033 | C15: =IF(B15="","",CHOOSE(WEEKDAY(B15,2),"Пн","Вт","Ср","Чт","Пт","Сб","Вс")) -> Вс | J15: =IF(B15="","",B15-MOD(WEEKDAY(B15,2)-3,7)) -> 46029 | K15: =IF(AND(B15>='План недели'!$B$4,B15<'План недели'!$D$4,D15<>"",G15<>"Отменён"),COUNTIFS($B$5:B15,">="&'План недели'!$B$4,$B$5:B15,"<"&'План недели'!$D$4,$D$5:D15,"<>",$G$5:G15,"<>Отменён"),"")
A16: =IF(B16="","","VIS_"&(YEAR(B16)*10000+MONTH(B16)*100+DAY(B16))&"_"&IF(COUNTIF($B$5:B16,B16)<10,"00"&COUNTIF($B$5:B16,B16),IF(COUNTIF($B$5:B16,B16)<100,"0"&COUNTIF($B$5:B16,B16),COUNTIF($B$5:B16,B16)))) -> VIS_20260112_001 | B16: 46034 | C16: =IF(B16="","",CHOOSE(WEEKDAY(B16,2),"Пн","Вт","Ср","Чт","Пт","Сб","Вс")) -> Пн | J16: =IF(B16="","",B16-MOD(WEEKDAY(B16,2)-3,7)) -> 46029 | K16: =IF(AND(B16>='План недели'!$B$4,B16<'План недели'!$D$4,D16<>"",G16<>"Отменён"),COUNTIFS($B$5:B16,">="&'План недели'!$B$4,$B$5:B16,"<"&'План недели'!$D$4,$D$5:D16,"<>",$G$5:G16,"<>Отменён"),"")
... A106: =IF(B106="","","VIS_"&(YEAR(B106)*10000+MONTH(B106)*100+DAY(B106))&"_"&IF(COUNTIF($B$5:B106,B106)<10,"00"&COUNTIF($B$5:B106,B106),IF(COUNTIF($B$5:B106,B106)<100,"0"&COUNTIF($B$5:B106,B106),COUNTIF($B$5:B106,B106)))) -> VIS_20260412_001 | B106: 46124 | C106: =IF(B106="","",CHOOSE(WEEKDAY(B106,2),"Пн","Вт","Ср","Чт","Пт","Сб","Вс")) -> Вс | J106: =IF(B106="","",B106-MOD(WEEKDAY(B106,2)-3,7)) -> 46120 | K106: =IF(AND(B106>='План недели'!$B$4,B106<'План недели'!$D$4,D106<>"",G106<>"Отменён"),COUNTIFS($B$5:B106,">="&'План недели'!$B$4,$B$5:B106,"<"&'План недели'!$D$4,$D$5:D106,"<>",$G$5:G106,"<>Отменён"),"")
A107: =IF(B107="","","VIS_"&(YEAR(B107)*10000+MONTH(B107)*100+DAY(B107))&"_"&IF(COUNTIF($B$5:B107,B107)<10,"00"&COUNTIF($B$5:B107,B107),IF(COUNTIF($B$5:B107,B107)<100,"0"&COUNTIF($B$5:B107,B107),COUNTIF($B$5:B107,B107)))) -> VIS_20260413_001 | B107: 46125 | C107: =IF(B107="","",CHOOSE(WEEKDAY(B107,2),"Пн","Вт","Ср","Чт","Пт","Сб","Вс")) -> Пн | D107: Ленинградский вокзал | E107: Струков Д.М. | F107: Фотопанорамная съёмка | G107: Выполнен | I107: 557 | J107: =IF(B107="","",B107-MOD(WEEKDAY(B107,2)-3,7)) -> 46120 | K107: =IF(AND(B107>='План недели'!$B$4,B107<'План недели'!$D$4,D107<>"",G107<>"Отменён"),COUNTIFS($B$5:B107,">="&'План недели'!$B$4,$B$5:B107,"<"&'План недели'!$D$4,$D$5:D107,"<>",$G$5:G107,"<>Отменён"),"")
A108: =IF(B108="","","VIS_"&(YEAR(B108)*10000+MONTH(B108)*100+DAY(B108))&"_"&IF(COUNTIF($B$5:B108,B108)<10,"00"&COUNTIF($B$5:B108,B108),IF(COUNTIF($B$5:B108,B108)<100,"0"&COUNTIF($B$5:B108,B108),COUNTIF($B$5:B108,B108)))) -> VIS_20260414_001 | B108: 46126 | C108: =IF(B108="","",CHOOSE(WEEKDAY(B108,2),"Пн","Вт","Ср","Чт","Пт","Сб","Вс")) -> Вт | D108: ст. Карамышевская | E108: Струков Д.М. | F108: Фотопанорамная съёмка | G108: Выполнен | I108: 445 | J108: =IF(B108="","",B108-MOD(WEEKDAY(B108,2)-3,7)) -> 46120 | K108: =IF(AND(B108>='План недели'!$B$4,B108<'План недели'!$D$4,D108<>"",G108<>"Отменён"),COUNTIFS($B$5:B108,">="&'План недели'!$B$4,$B$5:B108,"<"&'План недели'!$D$4,$D$5:D108,"<>",$G$5:G108,"<>Отменён"),"")
A109: =IF(B109="","","VIS_"&(YEAR(B109)*10000+MONTH(B109)*100+DAY(B109))&"_"&IF(COUNTIF($B$5:B109,B109)<10,"00"&COUNTIF($B$5:B109,B109),IF(COUNTIF($B$5:B109,B109)<100,"0"&COUNTIF($B$5:B109,B109),COUNTIF($B$5:B109,B109)))) -> VIS_20260415_001 | B109: 46127 | C109: =IF(B109="","",CHOOSE(WEEKDAY(B109,2),"Пн","Вт","Ср","Чт","Пт","Сб","Вс")) -> Ср | D109: Ленинградский вокзал | E109: Струков Д.М. | F109: Фотопанорамная съёмка | G109: Выполнен | I109: 557 | J109: =IF(B109="","",B109-MOD(WEEKDAY(B109,2)-3,7)) -> 46127 | K109: =IF(AND(B109>='План недели'!$B$4,B109<'План недели'!$D$4,D109<>"",G109<>"Отменён"),COUNTIFS($B$5:B109,">="&'План недели'!$B$4,$B$5:B109,"<"&'План недели'!$D$4,$D$5:D109,"<>",$G$5:G109,"<>Отменён"),"")
A110: =IF(B110="","","VIS_"&(YEAR(B110)*10000+MONTH(B110)*100+DAY(B110))&"_"&IF(COUNTIF($B$5:B110,B110)<10,"00"&COUNTIF($B$5:B110,B110),IF(COUNTIF($B$5:B110,B110)<100,"0"&COUNTIF($B$5:B110,B110),COUNTIF($B$5:B110,B110)))) -> VIS_20260416_001 | B110: 46128 | C110: =IF(B110="","",CHOOSE(WEEKDAY(B110,2),"Пн","Вт","Ср","Чт","Пт","Сб","Вс")) -> Чт | D110: ст. Остров мечты | E110: Струков Д.М. | F110: Фотопанорамная съёмка | G110: Выполнен | I110: 355 | J110: =IF(B110="","",B110-MOD(WEEKDAY(B110,2)-3,7)) -> 46127 | K110: =IF(AND(B110>='План недели'!$B$4,B110<'План недели'!$D$4,D110<>"",G110<>"Отменён"),COUNTIFS($B$5:B110,">="&'План недели'!$B$4,$B$5:B110,"<"&'План недели'!$D$4,$D$5:D110,"<>",$G$5:G110,"<>Отменён"),"")
A111: =IF(B111="","","VIS_"&(YEAR(B111)*10000+MONTH(B111)*100+DAY(B111))&"_"&IF(COUNTIF($B$5:B111,B111)<10,"00"&COUNTIF($B$5:B111,B111),IF(COUNTIF($B$5:B111,B111)<100,"0"&COUNTIF($B$5:B111,B111),COUNTIF($B$5:B111,B111)))) -> VIS_20260417_001 | B111: 46129 | C111: =IF(B111="","",CHOOSE(WEEKDAY(B111,2),"Пн","Вт","Ср","Чт","Пт","Сб","Вс")) -> Пт | D111: Ленинградский вокзал | E111: Струков Д.М. | F111: Фотопанорамная съёмка | G111: Выполнен | I111: 557 | J111: =IF(B111="","",B111-MOD(WEEKDAY(B111,2)-3,7)) -> 46127 | K111: =IF(AND(B111>='План недели'!$B$4,B111<'План недели'!$D$4,D111<>"",G111<>"Отменён"),COUNTIFS($B$5:B111,">="&'План недели'!$B$4,$B$5:B111,"<"&'План недели'!$D$4,$D$5:D111,"<>",$G$5:G111,"<>Отменён"),"")
A112: =IF(B112="","","VIS_"&(YEAR(B112)*10000+MONTH(B112)*100+DAY(B112))&"_"&IF(COUNTIF($B$5:B112,B112)<10,"00"&COUNTIF($B$5:B112,B112),IF(COUNTIF($B$5:B112,B112)<100,"0"&COUNTIF($B$5:B112,B112),COUNTIF($B$5:B112,B112)))) -> VIS_20260418_001 | B112: 46130 | C112: =IF(B112="","",CHOOSE(WEEKDAY(B112,2),"Пн","Вт","Ср","Чт","Пт","Сб","Вс")) -> Сб | J112: =IF(B112="","",B112-MOD(WEEKDAY(B112,2)-3,7)) -> 46127 | K112: =IF(AND(B112>='План недели'!$B$4,B112<'План недели'!$D$4,D112<>"",G112<>"Отменён"),COUNTIFS($B$5:B112,">="&'План недели'!$B$4,$B$5:B112,"<"&'План недели'!$D$4,$D$5:D112,"<>",$G$5:G112,"<>Отменён"),"")
A113: =IF(B113="","","VIS_"&(YEAR(B113)*10000+MONTH(B113)*100+DAY(B113))&"_"&IF(COUNTIF($B$5:B113,B113)<10,"00"&COUNTIF($B$5:B113,B113),IF(COUNTIF($B$5:B113,B113)<100,"0"&COUNTIF($B$5:B113,B113),COUNTIF($B$5:B113,B113)))) -> VIS_20260419_001 | B113: 46131 | C113: =IF(B113="","",CHOOSE(WEEKDAY(B113,2),"Пн","Вт","Ср","Чт","Пт","Сб","Вс")) -> Вс | J113: =IF(B113="","",B113-MOD(WEEKDAY(B113,2)-3,7)) -> 46127 | K113: =IF(AND(B113>='План недели'!$B$4,B113<'План недели'!$D$4,D113<>"",G113<>"Отменён"),COUNTIFS($B$5:B113,">="&'План недели'!$B$4,$B$5:B113,"<"&'План недели'!$D$4,$D$5:D113,"<>",$G$5:G113,"<>Отменён"),"")
A114: =IF(B114="","","VIS_"&(YEAR(B114)*10000+MONTH(B114)*100+DAY(B114))&"_"&IF(COUNTIF($B$5:B114,B114)<10,"00"&COUNTIF($B$5:B114,B114),IF(COUNTIF($B$5:B114,B114)<100,"0"&COUNTIF($B$5:B114,B114),COUNTIF($B$5:B114,B114)))) -> VIS_20260420_001 | B114: 46132 | C114: =IF(B114="","",CHOOSE(WEEKDAY(B114,2),"Пн","Вт","Ср","Чт","Пт","Сб","Вс")) -> Пн | D114: Ленинградский вокзал | E114: Сафонов М.С. | F114: Фотопанорамная съёмка | G114: Выполнен | I114: 557 | J114: =IF(B114="","",B114-MOD(WEEKDAY(B114,2)-3,7)) -> 46127 | K114: =IF(AND(B114>='План недели'!$B$4,B114<'План недели'!$D$4,D114<>"",G114<>"Отменён"),COUNTIFS($B$5:B114,">="&'План недели'!$B$4,$B$5:B114,"<"&'План недели'!$D$4,$D$5:D114,"<>",$G$5:G114,"<>Отменён"),"")
A115: =IF(B115="","","VIS_"&(YEAR(B115)*10000+MONTH(B115)*100+DAY(B115))&"_"&IF(COUNTIF($B$5:B115,B115)<10,"00"&COUNTIF($B$5:B115,B115),IF(COUNTIF($B$5:B115,B115)<100,"0"&COUNTIF($B$5:B115,B115),COUNTIF($B$5:B115,B115)))) -> VIS_20260421_001 | B115: 46133 | C115: =IF(B115="","",CHOOSE(WEEKDAY(B115,2),"Пн","Вт","Ср","Чт","Пт","Сб","Вс")) -> Вт | D115: ст. Бульвар Генерала Карбышева | E115: Сафонов М.С. | F115: Фотопанорамная съёмка | G115: Выполнен | I115: 200 | J115: =IF(B115="","",B115-MOD(WEEKDAY(B115,2)-3,7)) -> 46127 | K115: =IF(AND(B115>='План недели'!$B$4,B115<'План недели'!$D$4,D115<>"",G115<>"Отменён"),COUNTIFS($B$5:B115,">="&'План недели'!$B$4,$B$5:B115,"<"&'План недели'!$D$4,$D$5:D115,"<>",$G$5:G115,"<>Отменён"),"")
A116: =IF(B116="","","VIS_"&(YEAR(B116)*10000+MONTH(B116)*100+DAY(B116))&"_"&IF(COUNTIF($B$5:B116,B116)<10,"00"&COUNTIF($B$5:B116,B116),IF(COUNTIF($B$5:B116,B116)<100,"0"&COUNTIF($B$5:B116,B116),COUNTIF($B$5:B116,B116)))) -> VIS_20260422_001 | B116: 46134 | C116: =IF(B116="","",CHOOSE(WEEKDAY(B116,2),"Пн","Вт","Ср","Чт","Пт","Сб","Вс")) -> Ср | D116: Ленинградский вокзал | E116: Сафонов М.С. | F116: Фотопанорамная съёмка | G116: Выполнен | I116: 557 | J116: =IF(B116="","",B116-MOD(WEEKDAY(B116,2)-3,7)) -> 46134 | K116: =IF(AND(B116>='План недели'!$B$4,B116<'План недели'!$D$4,D116<>"",G116<>"Отменён"),COUNTIFS($B$5:B116,">="&'План недели'!$B$4,$B$5:B116,"<"&'План недели'!$D$4,$D$5:D116,"<>",$G$5:G116,"<>Отменён"),"")
A117: =IF(B117="","","VIS_"&(YEAR(B117)*10000+MONTH(B117)*100+DAY(B117))&"_"&IF(COUNTIF($B$5:B117,B117)<10,"00"&COUNTIF($B$5:B117,B117),IF(COUNTIF($B$5:B117,B117)<100,"0"&COUNTIF($B$5:B117,B117),COUNTIF($B$5:B117,B117)))) -> VIS_20260423_001 | B117: 46135 | C117: =IF(B117="","",CHOOSE(WEEKDAY(B117,2),"Пн","Вт","Ср","Чт","Пт","Сб","Вс")) -> Чт | D117: ст. ЗИЛ | E117: Сафонов М.С. | F117: Фотопанорамная съёмка | G117: Выполнен | I117: 194 | J117: =IF(B117="","",B117-MOD(WEEKDAY(B117,2)-3,7)) -> 46134 | K117: =IF(AND(B117>='План недели'!$B$4,B117<'План недели'!$D$4,D117<>"",G117<>"Отменён"),COUNTIFS($B$5:B117,">="&'План недели'!$B$4,$B$5:B117,"<"&'План недели'!$D$4,$D$5:D117,"<>",$G$5:G117,"<>Отменён"),"")
A118: =IF(B118="","","VIS_"&(YEAR(B118)*10000+MONTH(B118)*100+DAY(B118))&"_"&IF(COUNTIF($B$5:B118,B118)<10,"00"&COUNTIF($B$5:B118,B118),IF(COUNTIF($B$5:B118,B118)<100,"0"&COUNTIF($B$5:B118,B118),COUNTIF($B$5:B118,B118)))) -> VIS_20260424_001 | B118: 46136 | C118: =IF(B118="","",CHOOSE(WEEKDAY(B118,2),"Пн","Вт","Ср","Чт","Пт","Сб","Вс")) -> Пт | D118: Ленинградский вокзал | E118: Сафонов М.С. | F118: Фотопанорамная съёмка | G118: Выполнен | I118: 557 | J118: =IF(B118="","",B118-MOD(WEEKDAY(B118,2)-3,7)) -> 46134 | K118: =IF(AND(B118>='План недели'!$B$4,B118<'План недели'!$D$4,D118<>"",G118<>"Отменён"),COUNTIFS($B$5:B118,">="&'План недели'!$B$4,$B$5:B118,"<"&'План недели'!$D$4,$D$5:D118,"<>",$G$5:G118,"<>Отменён"),"")
A119: =IF(B119="","","VIS_"&(YEAR(B119)*10000+MONTH(B119)*100+DAY(B119))&"_"&IF(COUNTIF($B$5:B119,B119)<10,"00"&COUNTIF($B$5:B119,B119),IF(COUNTIF($B$5:B119,B119)<100,"0"&COUNTIF($B$5:B119,B119),COUNTIF($B$5:B119,B119)))) -> VIS_20260425_001 | B119: 46137 | C119: =IF(B119="","",CHOOSE(WEEKDAY(B119,2),"Пн","Вт","Ср","Чт","Пт","Сб","Вс")) -> Сб | J119: =IF(B119="","",B119-MOD(WEEKDAY(B119,2)-3,7)) -> 46134 | K119: =IF(AND(B119>='План недели'!$B$4,B119<'План недели'!$D$4,D119<>"",G119<>"Отменён"),COUNTIFS($B$5:B119,">="&'План недели'!$B$4,$B$5:B119,"<"&'План недели'!$D$4,$D$5:D119,"<>",$G$5:G119,"<>Отменён"),"")
A120: =IF(B120="","","VIS_"&(YEAR(B120)*10000+MONTH(B120)*100+DAY(B120))&"_"&IF(COUNTIF($B$5:B120,B120)<10,"00"&COUNTIF($B$5:B120,B120),IF(COUNTIF($B$5:B120,B120)<100,"0"&COUNTIF($B$5:B120,B120),COUNTIF($B$5:B120,B120)))) -> VIS_20260426_001 | B120: 46138 | C120: =IF(B120="","",CHOOSE(WEEKDAY(B120,2),"Пн","Вт","Ср","Чт","Пт","Сб","Вс")) -> Вс | J120: =IF(B120="","",B120-MOD(WEEKDAY(B120,2)-3,7)) -> 46134 | K120: =IF(AND(B120>='План недели'!$B$4,B120<'План недели'!$D$4,D120<>"",G120<>"Отменён"),COUNTIFS($B$5:B120,">="&'План недели'!$B$4,$B$5:B120,"<"&'План недели'!$D$4,$D$5:D120,"<>",$G$5:G120,"<>Отменён"),"")
A121: =IF(B121="","","VIS_"&(YEAR(B121)*10000+MONTH(B121)*100+DAY(B121))&"_"&IF(COUNTIF($B$5:B121,B121)<10,"00"&COUNTIF($B$5:B121,B121),IF(COUNTIF($B$5:B121,B121)<100,"0"&COUNTIF($B$5:B121,B121),COUNTIF($B$5:B121,B121)))) -> VIS_20260427_001 | B121: 46139 | C121: =IF(B121="","",CHOOSE(WEEKDAY(B121,2),"Пн","Вт","Ср","Чт","Пт","Сб","Вс")) -> Пн | D121: Ленинградский вокзал | E121: Сафонов М.С. | F121: Фотопанорамная съёмка | G121: Выполнен | I121: 557 | J121: =IF(B121="","",B121-MOD(WEEKDAY(B121,2)-3,7)) -> 46134 | K121: =IF(AND(B121>='План недели'!$B$4,B121<'План недели'!$D$4,D121<>"",G121<>"Отменён"),COUNTIFS($B$5:B121,">="&'План недели'!$B$4,$B$5:B121,"<"&'План недели'!$D$4,$D$5:D121,"<>",$G$5:G121,"<>Отменён"),"")
A122: =IF(B122="","","VIS_"&(YEAR(B122)*10000+MONTH(B122)*100+DAY(B122))&"_"&IF(COUNTIF($B$5:B122,B122)<10,"00"&COUNTIF($B$5:B122,B122),IF(COUNTIF($B$5:B122,B122)<100,"0"&COUNTIF($B$5:B122,B122),COUNTIF($B$5:B122,B122)))) -> VIS_20260428_001 | B122: 46140 | C122: =IF(B122="","",CHOOSE(WEEKDAY(B122,2),"Пн","Вт","Ср","Чт","Пт","Сб","Вс")) -> Вт | D122: ст. Звенигородская | E122: Сафонов М.С. | F122: Фотопанорамная съёмка | G122: Выполнен | I122: 366 | J122: =IF(B122="","",B122-MOD(WEEKDAY(B122,2)-3,7)) -> 46134 | K122: =IF(AND(B122>='План недели'!$B$4,B122<'План недели'!$D$4,D122<>"",G122<>"Отменён"),COUNTIFS($B$5:B122,">="&'План недели'!$B$4,$B$5:B122,"<"&'План недели'!$D$4,$D$5:D122,"<>",$G$5:G122,"<>Отменён"),"")
A123: =IF(B123="","","VIS_"&(YEAR(B123)*10000+MONTH(B123)*100+DAY(B123))&"_"&IF(COUNTIF($B$5:B123,B123)<10,"00"&COUNTIF($B$5:B123,B123),IF(COUNTIF($B$5:B123,B123)<100,"0"&COUNTIF($B$5:B123,B123),COUNTIF($B$5:B123,B123)))) -> VIS_20260428_002 | B123: 46140 | C123: =IF(B123="","",CHOOSE(WEEKDAY(B123,2),"Пн","Вт","Ср","Чт","Пт","Сб","Вс")) -> Вт | D123: Пл.10 РАЛ | E123: Сафонов М.С. | F123: Фотопанорамная съёмка | G123: Выполнен | I123: 15 | J123: =IF(B123="","",B123-MOD(WEEKDAY(B123,2)-3,7)) -> 46134 | K123: =IF(AND(B123>='План недели'!$B$4,B123<'План недели'!$D$4,D123<>"",G123<>"Отменён"),COUNTIFS($B$5:B123,">="&'План недели'!$B$4,$B$5:B123,"<"&'План недели'!$D$4,$D$5:D123,"<>",$G$5:G123,"<>Отменён"),"")
A124: =IF(B124="","","VIS_"&(YEAR(B124)*10000+MONTH(B124)*100+DAY(B124))&"_"&IF(COUNTIF($B$5:B124,B124)<10,"00"&COUNTIF($B$5:B124,B124),IF(COUNTIF($B$5:B124,B124)<100,"0"&COUNTIF($B$5:B124,B124),COUNTIF($B$5:B124,B124)))) -> VIS_20260429_001 | B124: 46141 | C124: =IF(B124="","",CHOOSE(WEEKDAY(B124,2),"Пн","Вт","Ср","Чт","Пт","Сб","Вс")) -> Ср | D124: Ленинградский вокзал | E124: Сафонов М.С. | F124: Фотопанорамная съёмка | G124: Выполнен | I124: 557 | J124: =IF(B124="","",B124-MOD(WEEKDAY(B124,2)-3,7)) -> 46141 | K124: =IF(AND(B124>='План недели'!$B$4,B124<'План недели'!$D$4,D124<>"",G124<>"Отменён"),COUNTIFS($B$5:B124,">="&'План недели'!$B$4,$B$5:B124,"<"&'План недели'!$D$4,$D$5:D124,"<>",$G$5:G124,"<>Отменён"),"")
A125: =IF(B125="","","VIS_"&(YEAR(B125)*10000+MONTH(B125)*100+DAY(B125))&"_"&IF(COUNTIF($B$5:B125,B125)<10,"00"&COUNTIF($B$5:B125,B125),IF(COUNTIF($B$5:B125,B125)<100,"0"&COUNTIF($B$5:B125,B125),COUNTIF($B$5:B125,B125)))) -> VIS_20260430_001 | B125: 46142 | C125: =IF(B125="","",CHOOSE(WEEKDAY(B125,2),"Пн","Вт","Ср","Чт","Пт","Сб","Вс")) -> Чт | D125: Пл.10 РАЛ | E125: Сафонов М.С. | F125: Фотопанорамная съёмка | G125: Выполнен | H125: Съёмка всех площадок РАЛ и МБЛ | I125: 15 | J125: =IF(B125="","",B125-MOD(WEEKDAY(B125,2)-3,7)) -> 46141 | K125: =IF(AND(B125>='План недели'!$B$4,B125<'План недели'!$D$4,D125<>"",G125<>"Отменён"),COUNTIFS($B$5:B125,">="&'План недели'!$B$4,$B$5:B125,"<"&'План недели'!$D$4,$D$5:D125,"<>",$G$5:G125,"<>Отменён"),"")
A126: =IF(B126="","","VIS_"&(YEAR(B126)*10000+MONTH(B126)*100+DAY(B126))&"_"&IF(COUNTIF($B$5:B126,B126)<10,"00"&COUNTIF($B$5:B126,B126),IF(COUNTIF($B$5:B126,B126)<100,"0"&COUNTIF($B$5:B126,B126),COUNTIF($B$5:B126,B126)))) -> VIS_20260430_002 | B126: 46142 | C126: =IF(B126="","",CHOOSE(WEEKDAY(B126,2),"Пн","Вт","Ср","Чт","Пт","Сб","Вс")) -> Чт | D126: Пл.12 РАЛ | E126: Сафонов М.С. | F126: Фотопанорамная съёмка | G126: Выполнен | H126: Съёмка всех площадок РАЛ и МБЛ | I126: 24 | J126: =IF(B126="","",B126-MOD(WEEKDAY(B126,2)-3,7)) -> 46141 | K126: =IF(AND(B126>='План недели'!$B$4,B126<'План недели'!$D$4,D126<>"",G126<>"Отменён"),COUNTIFS($B$5:B126,">="&'План недели'!$B$4,$B$5:B126,"<"&'План недели'!$D$4,$D$5:D126,"<>",$G$5:G126,"<>Отменён"),"")
A127: =IF(B127="","","VIS_"&(YEAR(B127)*10000+MONTH(B127)*100+DAY(B127))&"_"&IF(COUNTIF($B$5:B127,B127)<10,"00"&COUNTIF($B$5:B127,B127),IF(COUNTIF($B$5:B127,B127)<100,"0"&COUNTIF($B$5:B127,B127),COUNTIF($B$5:B127,B127)))) -> VIS_20260430_003 | B127: 46142 | C127: =IF(B127="","",CHOOSE(WEEKDAY(B127,2),"Пн","Вт","Ср","Чт","Пт","Сб","Вс")) -> Чт | D127: Пл.13 РАЛ | E127: Сафонов М.С. | F127: Фотопанорамная съёмка | G127: Выполнен | H127: Съёмка всех площадок РАЛ и МБЛ | I127: 22 | J127: =IF(B127="","",B127-MOD(WEEKDAY(B127,2)-3,7)) -> 46141 | K127: =IF(AND(B127>='План недели'!$B$4,B127<'План недели'!$D$4,D127<>"",G127<>"Отменён"),COUNTIFS($B$5:B127,">="&'План недели'!$B$4,$B$5:B127,"<"&'План недели'!$D$4,$D$5:D127,"<>",$G$5:G127,"<>Отменён"),"")
A128: =IF(B128="","","VIS_"&(YEAR(B128)*10000+MONTH(B128)*100+DAY(B128))&"_"&IF(COUNTIF($B$5:B128,B128)<10,"00"&COUNTIF($B$5:B128,B128),IF(COUNTIF($B$5:B128,B128)<100,"0"&COUNTIF($B$5:B128,B128),COUNTIF($B$5:B128,B128)))) -> VIS_20260430_004 | B128: 46142 | C128: =IF(B128="","",CHOOSE(WEEKDAY(B128,2),"Пн","Вт","Ср","Чт","Пт","Сб","Вс")) -> Чт | D128: Пл.14 РАЛ | E128: Сафонов М.С. | F128: Фотопанорамная съёмка | G128: Выполнен | H128: Съёмка всех площадок РАЛ и МБЛ | I128: 16 | J128: =IF(B128="","",B128-MOD(WEEKDAY(B128,2)-3,7)) -> 46141 | K128: =IF(AND(B128>='План недели'!$B$4,B128<'План недели'!$D$4,D128<>"",G128<>"Отменён"),COUNTIFS($B$5:B128,">="&'План недели'!$B$4,$B$5:B128,"<"&'План недели'!$D$4,$D$5:D128,"<>",$G$5:G128,"<>Отменён"),"")
A129: =IF(B129="","","VIS_"&(YEAR(B129)*10000+MONTH(B129)*100+DAY(B129))&"_"&IF(COUNTIF($B$5:B129,B129)<10,"00"&COUNTIF($B$5:B129,B129),IF(COUNTIF($B$5:B129,B129)<100,"0"&COUNTIF($B$5:B129,B129),COUNTIF($B$5:B129,B129)))) -> VIS_20260430_005 | B129: 46142 | C129: =IF(B129="","",CHOOSE(WEEKDAY(B129,2),"Пн","Вт","Ср","Чт","Пт","Сб","Вс")) -> Чт | D129: Пл.№1а | E129: Сафонов М.С. | F129: Фотопанорамная съёмка | G129: Выполнен | H129: Съёмка всех площадок РАЛ и МБЛ | I129: 24 | J129: =IF(B129="","",B129-MOD(WEEKDAY(B129,2)-3,7)) -> 46141 | K129: =IF(AND(B129>='План недели'!$B$4,B129<'План недели'!$D$4,D129<>"",G129<>"Отменён"),COUNTIFS($B$5:B129,">="&'План недели'!$B$4,$B$5:B129,"<"&'План недели'!$D$4,$D$5:D129,"<>",$G$5:G129,"<>Отменён"),"")
A130: =IF(B130="","","VIS_"&(YEAR(B130)*10000+MONTH(B130)*100+DAY(B130))&"_"&IF(COUNTIF($B$5:B130,B130)<10,"00"&COUNTIF($B$5:B130,B130),IF(COUNTIF($B$5:B130,B130)<100,"0"&COUNTIF($B$5:B130,B130),COUNTIF($B$5:B130,B130)))) -> VIS_20260430_006 | B130: 46142 | C130: =IF(B130="","",CHOOSE(WEEKDAY(B130,2),"Пн","Вт","Ср","Чт","Пт","Сб","Вс")) -> Чт | D130: Пл.№2а | E130: Сафонов М.С. | F130: Фотопанорамная съёмка | G130: Выполнен | H130: Съёмка всех площадок РАЛ и МБЛ | I130: 19 | J130: =IF(B130="","",B130-MOD(WEEKDAY(B130,2)-3,7)) -> 46141 | K130: =IF(AND(B130>='План недели'!$B$4,B130<'План недели'!$D$4,D130<>"",G130<>"Отменён"),COUNTIFS($B$5:B130,">="&'План недели'!$B$4,$B$5:B130,"<"&'План недели'!$D$4,$D$5:D130,"<>",$G$5:G130,"<>Отменён"),"")
...

Sheet Объекты
A1: Справочник объектов | B1: Справочник объектов | C1: Справочник объектов | D1: Справочник объектов | E1: Справочник объектов | F1: Справочник объектов | G1: Справочник объектов | H1: Справочник объектов | I1: Справочник объектов | J1: Справочник объектов | K1: Справочник объектов | L1: Справочник объектов | M1: Справочник объектов
A2: Жёлтый столбец «Количество точек» заполняется вручную: укажите, сколько точек снимается на каждом объекте. Ссылки и координаты остаются техническими данными дашборда. | B2: Обязательное новое поле — POINTS_COUNT: количество снимаемых точек на объекте. Жёлтые поля заполняются вручную; ссылки и координаты остаются техническими данными дашборда. | C2: Обязательное новое поле — POINTS_COUNT: количество снимаемых точек на объекте. Жёлтые поля заполняются вручную; ссылки и координаты остаются техническими данными дашборда. | D2: Обязательное новое поле — POINTS_COUNT: количество снимаемых точек на объекте. Жёлтые поля заполняются вручную; ссылки и координаты остаются техническими данными дашборда. | E2: Обязательное новое поле — POINTS_COUNT: количество снимаемых точек на объекте. Жёлтые поля заполняются вручную; ссылки и координаты остаются техническими данными дашборда. | F2: Обязательное новое поле — POINTS_COUNT: количество снимаемых точек на объекте. Жёлтые поля заполняются вручную; ссылки и координаты остаются техническими данными дашборда. | G2: Обязательное новое поле — POINTS_COUNT: количество снимаемых точек на объекте. Жёлтые поля заполняются вручную; ссылки и координаты остаются техническими данными дашборда. | H2: Обязательное новое поле — POINTS_COUNT: количество снимаемых точек на объекте. Жёлтые поля заполняются вручную; ссылки и координаты остаются техническими данными дашборда. | I2: Обязательное новое поле — POINTS_COUNT: количество снимаемых точек на объекте. Жёлтые поля заполняются вручную; ссылки и координаты остаются техническими данными дашборда. | J2: Обязательное новое поле — POINTS_COUNT: количество снимаемых точек на объекте. Жёлтые поля заполняются вручную; ссылки и координаты остаются техническими данными дашборда. | K2: Обязательное новое поле — POINTS_COUNT: количество снимаемых точек на объекте. Жёлтые поля заполняются вручную; ссылки и координаты остаются техническими данными дашборда. | L2: Обязательное новое поле — POINTS_COUNT: количество снимаемых точек на объекте. Жёлтые поля заполняются вручную; ссылки и координаты остаются техническими данными дашборда. | M2: Обязательное новое поле — POINTS_COUNT: количество снимаемых точек на объекте. Жёлтые поля заполняются вручную; ссылки и координаты остаются техническими данными дашборда.
A4: OBJECT_ID | B4: OBJECT_NAME | C4: POINTS_COUNT | D4: OBJECT_GROUP | E4: OBJECT_TYPE | F4: ADDRESS | G4: LATITUDE | H4: LONGITUDE | I4: YANDEX_MAP_URL | J4: ALBUM_URL | K4: PHOTO_PATH | L4: IS_ACTIVE | M4: COMMENT
A5: OBJ_001 | B5: Пл.10 РАЛ | C5: 15 | D5: Рублёво-Архангельская линия метрополитена. Этап 1 | E5: Линия метрополитена | G5: 55.763325 | H5: 37.516369 | I5: https://yandex.ru/maps/213/moscow/?ll=37.516952%2C55.763186&mode=whatshere&whatshere%5Bpoint%5D=37.516369%2C55.763325&whatshere%5Bzoom%5D=19.26&z=19.26 | J5: https://pa.sgnl.pro/public/album/b21ka | K5: C:\Users\tsemb\Desktop\test_photo\OBJ_001.png | L5: Да
A6: OBJ_002 | B6: Пл.12 РАЛ | C6: 24 | D6: Рублёво-Архангельская линия метрополитена. Этап 1 | E6: Линия метрополитена | G6: 55.770735 | H6: 37.500111 | I6: https://yandex.ru/maps/213/moscow/?ll=37.500135%2C55.771035&mode=whatshere&whatshere%5Bpoint%5D=37.500111%2C55.770735&whatshere%5Bzoom%5D=19.26&z=19.26 | J6: https://pa.sgnl.pro/public/album/r8qor | K6: C:\Users\tsemb\Desktop\test_photo\OBJ_002.png | L6: Да
A7: OBJ_003 | B7: Пл.13 РАЛ | C7: 22 | D7: Рублёво-Архангельская линия метрополитена. Этап 1 | E7: Линия метрополитена | G7: 55.78284 | H7: 37.481804 | I7: https://yandex.ru/maps/213/moscow/?ll=37.482005%2C55.782882&mode=whatshere&whatshere%5Bpoint%5D=37.481804%2C55.782840&whatshere%5Bzoom%5D=20.31&z=20.31 | J7: https://pa.sgnl.pro/public/album/rmyqr | K7: C:\Users\tsemb\Desktop\test_photo\OBJ_003.png | L7: Да
A8: OBJ_004 | B8: Пл.14 РАЛ | C8: 16 | D8: Рублёво-Архангельская линия метрополитена. Этап 1 | E8: Линия метрополитена | G8: 55.783037 | H8: 37.480585 | I8: https://yandex.ru/maps/213/moscow/?ll=37.480209%2C55.782987&mode=whatshere&whatshere%5Bpoint%5D=37.480585%2C55.783037&whatshere%5Bzoom%5D=19.11&z=19.11 | J8: https://pa.sgnl.pro/public/album/bxpdr | K8: C:\Users\tsemb\Desktop\test_photo\OBJ_004.png | L8: Да
A9: OBJ_005 | B9: ст. Бульвар Генерала Карбышева | C9: 200 | D9: Рублёво-Архангельская линия метрополитена. Этап 1 | E9: Линия метрополитена | G9: 55.785665 | H9: 37.464199 | I9: https://yandex.ru/maps/213/moscow/?ll=37.464615%2C55.785575&mode=whatshere&whatshere%5Bpoint%5D=37.464199%2C55.785665&whatshere%5Bzoom%5D=19.74&z=19.74 | J9: https://pa.sgnl.pro/public/album/b3gvr | K9: C:\Users\tsemb\Desktop\test_photo\OBJ_005.png | L9: Да
A10: OBJ_006 | B10: ст. Живописная | C10: 364 | D10: Рублёво-Архангельская линия метрополитена. Этап 1 | E10: Линия метрополитена | G10: 55.789194 | H10: 37.451494 | I10: https://yandex.ru/maps/213/moscow/?display-text=%D1%81%D1%82%D0%B0%D0%BD%D1%86%D0%B8%D1%8F%20%D0%B6%D0%B8%D0%B2%D0%BE%D0%BF%D0%B8%D1%81%D0%BD%D0%B0%D1%8F&filter=alternate_vertical%3AWhatWhere&ll=37.451541%2C55.789554&mode=search&sctx=ZAAAAAgCEAAaKAoSCY4j1uJTxEJAES49murJ5EtAEhIJWHIVi98Uuj8RVUyln3B2oz8iBgABAgMEBSgKOABAvZIHSAFqAnJ1nQHNzMw9oAEAqAEAvQFDuQMQggIj0YHRgtCw0L3RhtC40Y8g0LbQuNCy0L7Qv9C40YHQvdCw0Y%2BKAgCSAgMyMTOaAgxkZXNrdG9wLW1hcHM%3D&sll=37.451541%2C55.789554&sspn=0.003184%2C0.001188&text=%D1%81%D1%82%D0%B0%D0%BD%D1%86%D0%B8%D1%8F%20%D0%B6%D0%B8%D0%B2%D0%BE%D0%BF%D0%B8%D1%81%D0%BD%D0%B0%D1%8F&whatshere%5Bpoint%5D=37.451494%2C55.789194&whatshere%5Bzoom%5D=19&z=19 | J10: https://pa.sgnl.pro/public/album/bqggg | K10: C:\Users\tsemb\Desktop\test_photo\OBJ_006.png | L10: Да
A11: OBJ_007 | B11: ст. Звенигородская | C11: 366 | D11: Рублёво-Архангельская линия метрополитена. Этап 1 | E11: Линия метрополитена | G11: 55.765043 | H11: 37.511278 | I11: https://yandex.ru/maps/213/moscow/?ll=37.511946%2C55.765042&mode=whatshere&whatshere%5Bpoint%5D=37.511278%2C55.765043&whatshere%5Bzoom%5D=18.97&z=18.97 | J11: https://pa.sgnl.pro/public/album/a418a | K11: C:\Users\tsemb\Desktop\test_photo\OBJ_007.png | L11: Да
A12: OBJ_008 | B12: ст. Карамышевская | C12: 445 | D12: Рублёво-Архангельская линия метрополитена. Этап 1 | E12: Линия метрополитена | G12: 55.775786 | H12: 37.488061 | I12: https://yandex.ru/maps/213/moscow/?ll=37.488031%2C55.775786&mode=whatshere&whatshere%5Bpoint%5D=37.488061%2C55.775786&whatshere%5Bzoom%5D=20.55&z=20.55 | J12: https://pa.sgnl.pro/public/album/rzeyr | K12: C:\Users\tsemb\Desktop\test_photo\OBJ_008.png | L12: Да
A13: OBJ_009 | B13: ст. Липовая Роща | C13: 350 | D13: Рублёво-Архангельская линия метрополитена. Этап 1 | E13: Линия метрополитена | G13: 55.795765 | H13: 37.377671 | I13: https://yandex.ru/maps/213/moscow/?display-text=%D1%81%D1%82%D0%B0%D0%BD%D1%86%D0%B8%D1%8F%20%D0%B6%D0%B8%D0%B2%D0%BE%D0%BF%D0%B8%D1%81%D0%BD%D0%B0%D1%8F&filter=alternate_vertical%3AWhatWhere&ll=37.376657%2C55.794381&mode=search&sctx=ZAAAAAgCEAAaKAoSCY4j1uJTxEJAES49murJ5EtAEhIJWHIVi98Uuj8RVUyln3B2oz8iBgABAgMEBSgKOABAvJIHSAFqAnJ1nQHNzMw9oAEAqAEAvQFDuQMQggIj0YHRgtCw0L3RhtC40Y8g0LbQuNCy0L7Qv9C40YHQvdCw0Y%2BKAgCSAgMyMTOaAgxkZXNrdG9wLW1hcHM%3D&sll=37.376657%2C55.794381&sspn=0.012735%2C0.004751&text=%D1%81%D1%82%D0%B0%D0%BD%D1%86%D0%B8%D1%8F%20%D0%B6%D0%B8%D0%B2%D0%BE%D0%BF%D0%B8%D1%81%D0%BD%D0%B0%D1%8F&whatshere%5Bpoint%5D=37.377671%2C55.795765&whatshere%5Bzoom%5D=17&z=17 | J13: https://pa.sgnl.pro/public/album/bdmm6 | K13: C:\Users\tsemb\Desktop\test_photo\OBJ_009.png | L13: Да
A14: OBJ_010 | B14: ст. Строгино | C14: 334 | D14: Рублёво-Архангельская линия метрополитена. Этап 1 | E14: Линия метрополитена | G14: 55.803678 | H14: 37.403089 | I14: https://yandex.ru/maps/213/moscow/?display-text=%D1%81%D1%82%D0%B0%D0%BD%D1%86%D0%B8%D1%8F%20%D0%B6%D0%B8%D0%B2%D0%BE%D0%BF%D0%B8%D1%81%D0%BD%D0%B0%D1%8F&filter=alternate_vertical%3AWhatWhere&ll=37.403279%2C55.803599&mode=search&sctx=ZAAAAAgCEAAaKAoSCY4j1uJTxEJAES49murJ5EtAEhIJWHIVi98Uuj8RVUyln3B2oz8iBgABAgMEBSgKOABAvJIHSAFqAnJ1nQHNzMw9oAEAqAEAvQFDuQMQggIj0YHRgtCw0L3RhtC40Y8g0LbQuNCy0L7Qv9C40YHQvdCw0Y%2BKAgCSAgMyMTOaAgxkZXNrdG9wLW1hcHM%3D&sll=37.403279%2C55.803599&sspn=0.003184%2C0.001187&text=%D1%81%D1%82%D0%B0%D0%BD%D1%86%D0%B8%D1%8F%20%D0%B6%D0%B8%D0%B2%D0%BE%D0%BF%D0%B8%D1%81%D0%BD%D0%B0%D1%8F&whatshere%5Bpoint%5D=37.403089%2C55.803678&whatshere%5Bzoom%5D=19&z=19 | J14: https://pa.sgnl.pro/public/album/b2eew | K14: C:\Users\tsemb\Desktop\test_photo\OBJ_010.png | L14: Да
A15: OBJ_011 | B15: ст. ЗИЛ | C15: 194 | D15: Бирюлёвская линия метрополитена | E15: Линия метрополитена | G15: 55.698813 | H15: 37.646635 | I15: https://yandex.ru/maps/213/moscow/?ll=37.646763%2C55.698830&mode=whatshere&whatshere%5Bpoint%5D=37.646635%2C55.698813&whatshere%5Bzoom%5D=20.3&z=20.3 | J15: https://pa.sgnl.pro/public/album/r866l | K15: C:\Users\tsemb\Desktop\test_photo\OBJ_011.png | L15: Да
A16: OBJ_012 | B16: ст. Остров мечты | C16: 355 | D16: Бирюлёвская линия метрополитена | E16: Линия метрополитена | G16: 55.692665 | H16: 37.666723 | I16: https://yandex.ru/maps/213/moscow/?ll=37.666834%2C55.692642&mode=whatshere&whatshere%5Bpoint%5D=37.666723%2C55.692665&whatshere%5Bzoom%5D=20.7&z=20.7 | J16: https://pa.sgnl.pro/public/album/rm11v | K16: C:\Users\tsemb\Desktop\test_photo\OBJ_012.png | L16: Да
... A21: OBJ_017 | B21: Ситуационный центр | C21: 151 | D21: Другие объекты | E21: Другой объект | G21: 55.770785 | H21: 37.591084 | I21: https://yandex.ru/maps/213/moscow/?l=stv%2Csta&ll=37.591481%2C55.770942&mode=whatshere&whatshere%5Bpoint%5D=37.591084%2C55.770785&whatshere%5Bzoom%5D=20&z=20 | J21: https://pa.sgnl.pro/public/album/rlww8 | K21: C:\Users\tsemb\Desktop\test_photo\OBJ_017.png | L21: Да
A22: OBJ_018 | B22: ст. Новорижская | C22: 526 | D22: Рублёво-Архангельская линия метрополитена. Этап 2 | E22: Линия метрополитена | F22: между Ильинским шоссе и 23-м км Новорижского шоссе | G22: 55.8005 | H22: 37.288 | I22: https://yandex.ru/maps/?ll=37.288000%2C55.800500&z=16&pt=37.288000%2C55.800500,pm2rdm | J22: https://pa.sgnl.pro/public/album/rpvvx | L22: Да
A23: OBJ_019 | B23: ст. СберСити | C23: 602 | D23: Рублёво-Архангельская линия метрополитена. Этап 2 | E23: Линия метрополитена | F23: Москва, микрорайон Рублёво-Архангельское | G23: 55.794767 | H23: 37.330129 | I23: https://yandex.ru/maps/213/moscow/?ll=37.333132%2C55.794514&mode=whatshere&pt=37.336449%2C55.790530%2Cpm2rdm&whatshere%5Bpoint%5D=37.330129%2C55.794767&whatshere%5Bzoom%5D=17.2&z=17.2 | J23: https://pa.sgnl.pro/public/album/r9993 | L23: Да
A24: =IF(B24="","","OBJ_"&TEXT(ROW()-4,"000")) | L24: Да

Sheet Справочники
A1: Справочники | B1: Справочники | C1: Справочники | D1: Справочники | E1: Справочники | F1: Справочники | G1: Справочники | H1: Справочники | I1: Справочники | J1: Справочники | K1: Справочники
A2: Списки используются в выпадающих полях календаря и карточек объектов. Добавляйте новые значения в соответствующий столбец. | B2: Списки используются в выпадающих полях календаря и карточек объектов. Добавляйте новые значения в соответствующий столбец. | C2: Списки используются в выпадающих полях календаря и карточек объектов. Добавляйте новые значения в соответствующий столбец. | D2: Списки используются в выпадающих полях календаря и карточек объектов. Добавляйте новые значения в соответствующий столбец. | E2: Списки используются в выпадающих полях календаря и карточек объектов. Добавляйте новые значения в соответствующий столбец. | F2: Списки используются в выпадающих полях календаря и карточек объектов. Добавляйте новые значения в соответствующий столбец. | G2: Списки используются в выпадающих полях календаря и карточек объектов. Добавляйте новые значения в соответствующий столбец. | H2: Списки используются в выпадающих полях календаря и карточек объектов. Добавляйте новые значения в соответствующий столбец. | I2: Списки используются в выпадающих полях календаря и карточек объектов. Добавляйте новые значения в соответствующий столбец. | J2: Списки используются в выпадающих полях календаря и карточек объектов. Добавляйте новые значения в соответствующий столбец. | K2: Списки используются в выпадающих полях календаря и карточек объектов. Добавляйте новые значения в соответствующий столбец.
A4: Статусы | C4: Сотрудники | E4: Активность | G4: Виды работ | H4: Значок на карте | I4: Типы объектов | K4: Группы объектов
A5: Запланирован | C5: Сафонов М.С. | E5: Да | G5: Фотопанорамная съёмка | H5: Панорамная камера | I5: Линия метрополитена | K5: Рублёво-Архангельская линия метрополитена. Этап 1
A6: Выполнен | C6: Струков Д.М. | E6: Да | G6: Лазерное сканирование | H6: Лазерный сканер | I6: Другой объект | K6: Рублёво-Архангельская линия метрополитена. Этап 2
A7: Перенесён | K7: Бирюлёвская линия метрополитена
A8: Отменён | K8: Другие объекты
A9: Требует подтверждения
A10: Завершено
